<h1 id="使用-promise-进行错误处理">使用 promise 进行错误处理</h1>
<p>Promise 链在错误（error）处理中十分强大。当一个 promise 被 reject 时，控制权将移交至最近的 rejection 处理程序（handler）。这在实际开发中非常方便。</p>
<p>例如，下面代码中所 <code>fetch</code> 的 URL 是错的（没有这个网站），<code>.catch</code> 对这个 error 进行了处理：</p>
<pre><code class="language-js">
fetch(<span class="hljs-string">&#x27;https://no-such-server.blabla&#x27;</span>) <span class="hljs-comment">// rejects</span>

  .then(<span class="hljs-function"><span class="hljs-params">response</span> =&gt;</span> response.json())
  .catch(<span class="hljs-function"><span class="hljs-params">err</span> =&gt;</span> alert(err)) <span class="hljs-comment">// TypeError: failed to fetch（这里的文字可能有所不同）</span></code></pre>
<p>正如你所看到的，<code>.catch</code> 不必是立即的。它可能在一个或多个 <code>.then</code> 之后出现。</p>
<p>或者，可能该网站一切正常，但响应不是有效的 JSON。捕获所有 error 的最简单的方法是，将 <code>.catch</code> 附加到链的末尾：</p>
<pre><code class="language-js">fetch(<span class="hljs-string">&#x27;/article/promise-chaining/user.json&#x27;</span>)
  .then(<span class="hljs-function"><span class="hljs-params">response</span> =&gt;</span> response.json())
  .then(<span class="hljs-function"><span class="hljs-params">user</span> =&gt;</span> fetch(<span class="hljs-string">`https://api.github.com/users/<span class="hljs-subst">${user.name}</span>`</span>))
  .then(<span class="hljs-function"><span class="hljs-params">response</span> =&gt;</span> response.json())
  .then(<span class="hljs-function"><span class="hljs-params">githubUser</span> =&gt;</span> <span class="hljs-keyword">new</span> <span class="hljs-built_in">Promise</span>(<span class="hljs-function">(<span class="hljs-params">resolve, reject</span>) =&gt;</span> {
    <span class="hljs-keyword">let</span> img = <span class="hljs-built_in">document</span>.createElement(<span class="hljs-string">&#x27;img&#x27;</span>);
    img.src = githubUser.avatar_url;
    img.className = <span class="hljs-string">&quot;promise-avatar-example&quot;</span>;
    <span class="hljs-built_in">document</span>.body.append(img);

    <span class="hljs-built_in">setTimeout</span>(<span class="hljs-function">() =&gt;</span> {
      img.remove();
      resolve(githubUser);
    }, <span class="hljs-number">3000</span>);
  }))

  .catch(<span class="hljs-function"><span class="hljs-params">error</span> =&gt;</span> alert(error.message));
</code></pre>
<p>通常情况下，这样的 <code>.catch</code> 根本不会被触发。但是如果上述任意一个 promise 被 reject（网络问题或者无效的 json 或其他），<code>.catch</code> 就会捕获它。</p>
<h2 id="隐式-trycatch">隐式 try..catch</h2>
<p>Promise 的执行者（executor）和 promise 的处理程序（handler）周围有一个“隐式的 <code>try..catch</code>”。如果发生异常，它（译注：指异常）就会被捕获，并被视为 rejection 进行处理。</p>
<p>例如，下面这段代码：</p>
<pre><code class="language-js"><span class="hljs-keyword">new</span> <span class="hljs-built_in">Promise</span>(<span class="hljs-function">(<span class="hljs-params">resolve, reject</span>) =&gt;</span> {

  <span class="hljs-keyword">throw</span> <span class="hljs-keyword">new</span> <span class="hljs-built_in">Error</span>(<span class="hljs-string">&quot;Whoops!&quot;</span>);

}).catch(alert); <span class="hljs-comment">// Error: Whoops!</span></code></pre>
<p>……与下面这段代码工作上完全相同：</p>
<pre><code class="language-js"><span class="hljs-keyword">new</span> <span class="hljs-built_in">Promise</span>(<span class="hljs-function">(<span class="hljs-params">resolve, reject</span>) =&gt;</span> {

  reject(<span class="hljs-keyword">new</span> <span class="hljs-built_in">Error</span>(<span class="hljs-string">&quot;Whoops!&quot;</span>));

}).catch(alert); <span class="hljs-comment">// Error: Whoops!</span></code></pre>
<p>在 executor 周围的“隐式 <code>try..catch</code>”自动捕获了 error，并将其变为 rejected promise。</p>
<p>这不仅仅发生在 executor 函数中，同样也发生在其 handler 中。如果我们在 <code>.then</code> 处理程序（handler）中 <code>throw</code>，这意味着 promise 被 rejected，因此控制权移交至最近的 error 处理程序（handler）。</p>
<p>这是一个例子：</p>
<pre><code class="language-js"><span class="hljs-keyword">new</span> <span class="hljs-built_in">Promise</span>(<span class="hljs-function">(<span class="hljs-params">resolve, reject</span>) =&gt;</span> {
  resolve(<span class="hljs-string">&quot;ok&quot;</span>);
}).then(<span class="hljs-function">(<span class="hljs-params">result</span>) =&gt;</span> {

  <span class="hljs-keyword">throw</span> <span class="hljs-keyword">new</span> <span class="hljs-built_in">Error</span>(<span class="hljs-string">&quot;Whoops!&quot;</span>); <span class="hljs-comment">// reject 这个 promise</span>

}).catch(alert); <span class="hljs-comment">// Error: Whoops!</span></code></pre>
<p>对于所有的 error 都会发生这种情况，而不仅仅是由 <code>throw</code> 语句导致的这些 error。例如，一个编程错误：</p>
<pre><code class="language-js"><span class="hljs-keyword">new</span> <span class="hljs-built_in">Promise</span>(<span class="hljs-function">(<span class="hljs-params">resolve, reject</span>) =&gt;</span> {
  resolve(<span class="hljs-string">&quot;ok&quot;</span>);
}).then(<span class="hljs-function">(<span class="hljs-params">result</span>) =&gt;</span> {

  blabla(); <span class="hljs-comment">// 没有这个函数</span>

}).catch(alert); <span class="hljs-comment">// ReferenceError: blabla is not defined</span></code></pre>
<p>最后的 <code>.catch</code> 不仅会捕获显式的 rejection，还会捕获它上面的处理程序（handler）中意外出现的 error。</p>
<h2 id="再次抛出（rethrowing）">再次抛出（Rethrowing）</h2>
<p>正如我们已经注意到的，链尾端的 <code>.catch</code> 的表现有点像 <code>try..catch</code>。我们可能有许多个 <code>.then</code> 处理程序（handler），然后在尾端使用一个 <code>.catch</code> 处理上面的所有 error。</p>
<p>在常规的 <code>try..catch</code> 中，我们可以分析错误（error），如果我们无法处理它，可以将其再次抛出。对于 promise 来说，这也是可以的。</p>
<p>如果我们在 <code>.catch</code> 中 <code>throw</code>，那么控制权就会被移交到下一个最近的 error 处理程序（handler）。如果我们处理该 error 并正常完成，那么它将继续到最近的成功的 <code>.then</code> 处理程序（handler）。</p>
<p>在下面这个例子中，<code>.catch</code> 成功处理了 error：</p>
<pre><code class="language-js"><span class="hljs-comment">// 执行流：catch -&gt; then</span>
<span class="hljs-keyword">new</span> <span class="hljs-built_in">Promise</span>(<span class="hljs-function">(<span class="hljs-params">resolve, reject</span>) =&gt;</span> {

  <span class="hljs-keyword">throw</span> <span class="hljs-keyword">new</span> <span class="hljs-built_in">Error</span>(<span class="hljs-string">&quot;Whoops!&quot;</span>);

}).catch(<span class="hljs-function"><span class="hljs-keyword">function</span>(<span class="hljs-params">error</span>) </span>{

  alert(<span class="hljs-string">&quot;The error is handled, continue normally&quot;</span>);

}).then(<span class="hljs-function">() =&gt;</span> alert(<span class="hljs-string">&quot;Next successful handler runs&quot;</span>));</code></pre>
<p>这里 <code>.catch</code> 块正常完成。所以下一个成功的 <code>.then</code> 处理程序（handler）就会被调用。</p>
<p>在下面的例子中，我们可以看到 <code>.catch</code> 的另一种情况。<code>(*)</code> 行的处理程序（handler）捕获了 error，但无法处理它（例如，它只知道如何处理 <code>URIError</code>），所以它将其再次抛出：</p>
<pre><code class="language-js"><span class="hljs-comment">// 执行流：catch -&gt; catch</span>
<span class="hljs-keyword">new</span> <span class="hljs-built_in">Promise</span>(<span class="hljs-function">(<span class="hljs-params">resolve, reject</span>) =&gt;</span> {

  <span class="hljs-keyword">throw</span> <span class="hljs-keyword">new</span> <span class="hljs-built_in">Error</span>(<span class="hljs-string">&quot;Whoops!&quot;</span>);

}).catch(<span class="hljs-function"><span class="hljs-keyword">function</span>(<span class="hljs-params">error</span>) </span>{ <span class="hljs-comment">// (*)</span>

  <span class="hljs-keyword">if</span> (error <span class="hljs-keyword">instanceof</span> <span class="hljs-built_in">URIError</span>) {
    <span class="hljs-comment">// 处理它</span>
  } <span class="hljs-keyword">else</span> {
    alert(<span class="hljs-string">&quot;Can&#x27;t handle such error&quot;</span>);


    <span class="hljs-keyword">throw</span> error; <span class="hljs-comment">// 再次抛出此 error 或另外一个 error，执行将跳转至下一个 catch</span>

  }

}).then(<span class="hljs-function"><span class="hljs-keyword">function</span>(<span class="hljs-params"></span>) </span>{
  <span class="hljs-comment">/* 不在这里运行 */</span>
}).catch(<span class="hljs-function"><span class="hljs-params">error</span> =&gt;</span> { <span class="hljs-comment">// (**)</span>

  alert(<span class="hljs-string">`The unknown error has occurred: <span class="hljs-subst">${error}</span>`</span>);
  <span class="hljs-comment">// 不会返回任何内容 =&gt; 执行正常进行</span>

});</code></pre>
<p>执行从第一个 <code>.catch</code> <code>(*)</code> 沿着链跳转至下一个 <code>(**)</code>。</p>
<h2 id="未处理的-rejection">未处理的 rejection</h2>
<p>当一个 error 没有被处理会发生什么？例如，我们忘了在链的尾端附加 <code>.catch</code>，像这样：</p>
<pre><code class="language-js"><span class="hljs-keyword">new</span> <span class="hljs-built_in">Promise</span>(<span class="hljs-function"><span class="hljs-keyword">function</span>(<span class="hljs-params"></span>) </span>{
  noSuchFunction(); <span class="hljs-comment">// 这里出现 error（没有这个函数）</span>
})
  .then(<span class="hljs-function">() =&gt;</span> {
    <span class="hljs-comment">// 一个或多个成功的 promise 处理程序（handler）</span>
  }); <span class="hljs-comment">// 尾端没有 .catch！</span></code></pre>
<p>如果出现 error，promise 的状态将变为 &quot;rejected&quot;，然后执行应该跳转至最近的 rejection 处理程序（handler）。但是上面这个例子中并没有这样的处理程序（handler）。因此 error 会“卡住（stuck）”。没有代码来处理它。</p>
<p>在实际开发中，就像代码中常规的未处理的 error 一样，这意味着某些东西出了问题。</p>
<p>当发生一个常规的错误（error）并且未被 <code>try..catch</code> 捕获时会发生什么？脚本死了，并在控制台（console）中留下了一个信息。对于在 promise 中未被处理的 rejection，也会发生类似的事儿。</p>
<p>JavaScript 引擎会跟踪此类 rejection，在这种情况下会生成一个全局的 error。如果你运行上面这个代码，你可以在控制台（console）中看到。</p>
<p>在浏览器中，我们可以使用 <code>unhandledrejection</code> 事件来捕获这类 error：</p>
<pre><code class="language-js">
<span class="hljs-built_in">window</span>.addEventListener(<span class="hljs-string">&#x27;unhandledrejection&#x27;</span>, <span class="hljs-function"><span class="hljs-keyword">function</span>(<span class="hljs-params">event</span>) </span>{
  <span class="hljs-comment">// 这个事件对象有两个特殊的属性：</span>
  alert(event.promise); <span class="hljs-comment">// [object Promise] - 生成该全局 error 的 promise</span>
  alert(event.reason); <span class="hljs-comment">// Error: Whoops! - 未处理的 error 对象</span>
});


<span class="hljs-keyword">new</span> <span class="hljs-built_in">Promise</span>(<span class="hljs-function"><span class="hljs-keyword">function</span>(<span class="hljs-params"></span>) </span>{
  <span class="hljs-keyword">throw</span> <span class="hljs-keyword">new</span> <span class="hljs-built_in">Error</span>(<span class="hljs-string">&quot;Whoops!&quot;</span>);
}); <span class="hljs-comment">// 没有用来处理 error 的 catch</span></code></pre>
<p>这个事件是 <a href="https://html.spec.whatwg.org/multipage/webappapis.html#unhandled-promise-rejections">HTML 标准</a> 的一部分。</p>
<p>如果出现了一个 error，并且在这儿没有 <code>.catch</code>，那么 <code>unhandledrejection</code> 处理程序（handler）就会被触发，并获取具有 error 相关信息的 <code>event</code> 对象，所以我们就能做一些后续处理了。</p>
<p>通常此类 error 是无法恢复的，所以我们最好的解决方案是将问题告知用户，并且可以将事件报告给服务器。</p>
<p>在 Node.js 等非浏览器环境中，有其他用于跟踪未处理的 error 的方法。</p>
<h2 id="总结">总结</h2>
<ul>
<li><code>.catch</code> 处理 promise 中的各种 error：在 <code>reject()</code> 调用中的，或者在处理程序（handler）中抛出的（thrown）error。</li>
<li>我们应该将 <code>.catch</code> 准确地放到我们想要处理 error，并知道如何处理这些 error 的地方。处理程序应该分析 error（可以自定义 error 类来帮助分析）并再次抛出未知的 error（可能它们是编程错误）。</li>
<li>如果没有办法从 error 中恢复的话，不使用 <code>.catch</code> 也可以。</li>
<li>在任何情况下我们都应该有 <code>unhandledrejection</code> 事件处理程序（用于浏览器，以及其他环境的模拟），以跟踪未处理的 error 并告知用户（可能还有我们的服务器）有关信息，以使我们的应用程序永远不会“死掉”。</li>
</ul>
<h2 id="补充内容">补充内容</h2>
<pre><code class="language-smart">为了更清晰地讲解 promise，本文经过大幅重写，以下内容是重写时被优化掉的内容，译者认为还是很有学习价值的，遂保留下来供大家学习。</code></pre>
<h3 id="fetch-错误处理示例">Fetch 错误处理示例</h3>
<p>让我们改进用户加载（user-loading）示例的错误处理。</p>
<p>当请求无法发出时，<a href="mdn:api/WindowOrWorkerGlobalScope/fetch">fetch</a> reject 会返回 promise。例如，远程服务器无法访问，或者 URL 异常。但是如果远程服务器返回响应错误 404，甚至是错误 500，这些都被认为是合法的响应。</p>
<p>如果在 <code>(*)</code> 行，服务器返回一个错误 500 的非 JSON（non-JSON）页面该怎么办？如果没有这个用户，GitHub 返回错误 404 的页面又该怎么办呢？</p>
<pre><code class="language-js">fetch(<span class="hljs-string">&#x27;no-such-user.json&#x27;</span>) <span class="hljs-comment">// (*)</span>
  .then(<span class="hljs-function"><span class="hljs-params">response</span> =&gt;</span> response.json())
  .then(<span class="hljs-function"><span class="hljs-params">user</span> =&gt;</span> fetch(<span class="hljs-string">`https://api.github.com/users/<span class="hljs-subst">${user.name}</span>`</span>)) <span class="hljs-comment">// (**)</span>
  .then(<span class="hljs-function"><span class="hljs-params">response</span> =&gt;</span> response.json())
  .catch(alert); <span class="hljs-comment">// SyntaxError: Unexpected token &lt; in JSON at position 0</span>
  <span class="hljs-comment">// ...</span></code></pre>
<p>到目前为止，代码试图以 JSON 格式加载响应数据，但无论如何都会因为语法错误而失败。你可以通过执行上述例子来查看相关信息，因为文件 <code>no-such-user.json</code> 不存在。</p>
<p>这有点糟糕，因为错误只是落在链上，并没有相关细节信息：什么失败了，在哪里失败的。</p>
<p>因此我们多添加一步：我们应该检查具有 HTTP 状态的 <code>response.status</code> 属性，如果不是 200 就抛出错误。</p>
<pre><code class="language-js"><span class="hljs-class"><span class="hljs-keyword">class</span> <span class="hljs-title">HttpError</span> <span class="hljs-keyword">extends</span> <span class="hljs-title">Error</span> </span>{ <span class="hljs-comment">// (1)</span>
  <span class="hljs-keyword">constructor</span>(response) {
    <span class="hljs-built_in">super</span>(<span class="hljs-string">`<span class="hljs-subst">${response.status}</span> for <span class="hljs-subst">${response.url}</span>`</span>);
    <span class="hljs-built_in">this</span>.name = <span class="hljs-string">&#x27;HttpError&#x27;</span>;
    <span class="hljs-built_in">this</span>.response = response;
  }
}

<span class="hljs-function"><span class="hljs-keyword">function</span> <span class="hljs-title">loadJson</span>(<span class="hljs-params">url</span>) </span>{ <span class="hljs-comment">// (2)</span>
  <span class="hljs-keyword">return</span> fetch(url)
    .then(<span class="hljs-function"><span class="hljs-params">response</span> =&gt;</span> {
      <span class="hljs-keyword">if</span> (response.status == <span class="hljs-number">200</span>) {
        <span class="hljs-keyword">return</span> response.json();
      } <span class="hljs-keyword">else</span> {
        <span class="hljs-keyword">throw</span> <span class="hljs-keyword">new</span> HttpError(response);
      }
    })
}

loadJson(<span class="hljs-string">&#x27;no-such-user.json&#x27;</span>) <span class="hljs-comment">// (3)</span>
  .catch(alert); <span class="hljs-comment">// HttpError: 404 for .../no-such-user.json</span></code></pre>
<ol>
<li>我们为 HTTP 错误创建一个自定义类用于区分 HTTP 错误和其他类型错误。此外，新的类有一个 constructor，它接受 <code>response</code> 对象，并将其保存到 error 中。因此，错误处理（error-handling）代码就能够获得响应数据了。</li>
<li>然后我们将请求（requesting）和错误处理代码包装进一个函数，它能够 fetch <code>url</code> <strong>并</strong> 将所有状态码不是 200 视为错误。这很方便，因为我们通常需要这样的逻辑。</li>
<li>现在 <code>alert</code> 显示更多有用的描述信息。</li>
</ol>
<p>拥有我们自己的错误处理类的好处是我们可以使用 <code>instanceof</code> 很容易地在错误处理代码中检查错误。</p>
<p>例如，我们可以创建请求，如果我们得到 404 就可以告知用户修改信息。</p>
<p>下面的代码从 GitHub 加载给定名称的用户。如果没有这个用户，它将告知用户填写正确的名称：</p>
<pre><code class="language-js"><span class="hljs-function"><span class="hljs-keyword">function</span> <span class="hljs-title">demoGithubUser</span>(<span class="hljs-params"></span>) </span>{
  <span class="hljs-keyword">let</span> name = prompt(<span class="hljs-string">&quot;Enter a name?&quot;</span>, <span class="hljs-string">&quot;iliakan&quot;</span>);

  <span class="hljs-keyword">return</span> loadJson(<span class="hljs-string">`https://api.github.com/users/<span class="hljs-subst">${name}</span>`</span>)
    .then(<span class="hljs-function"><span class="hljs-params">user</span> =&gt;</span> {
      alert(<span class="hljs-string">`Full name: <span class="hljs-subst">${user.name}</span>.`</span>);
      <span class="hljs-keyword">return</span> user;
    })
    .catch(<span class="hljs-function"><span class="hljs-params">err</span> =&gt;</span> {

      <span class="hljs-keyword">if</span> (err <span class="hljs-keyword">instanceof</span> HttpError &amp;&amp; err.response.status == <span class="hljs-number">404</span>) {

        alert(<span class="hljs-string">&quot;No such user, please reenter.&quot;</span>);
        <span class="hljs-keyword">return</span> demoGithubUser();
      } <span class="hljs-keyword">else</span> {
        <span class="hljs-keyword">throw</span> err; <span class="hljs-comment">// (*)</span>
      }
    });
}

demoGithubUser();</code></pre>
<p>请注意：这里的 <code>.catch</code> 会捕获所有错误，但是它仅仅“知道如何处理” <code>HttpError 404</code>。在那种特殊情况下，它意味着没有这样的用户，而 <code>.catch</code> 仅仅在这种情况下重试。</p>
<p>对于其他错误，它不知道会出现什么问题。可能是编程错误或者其他错误。所以它仅仅是在 <code>(*)</code> 行再次抛出。</p>
<h3 id="其他">其他</h3>
<p>如果我们有加载指示（load-indication），<code>.finally</code> 是一个很好的处理程序（handler），在 fetch 完成时停止它：</p>
<pre><code class="language-js"><span class="hljs-function"><span class="hljs-keyword">function</span> <span class="hljs-title">demoGithubUser</span>(<span class="hljs-params"></span>) </span>{
  <span class="hljs-keyword">let</span> name = prompt(<span class="hljs-string">&quot;Enter a name?&quot;</span>, <span class="hljs-string">&quot;iliakan&quot;</span>);


  <span class="hljs-built_in">document</span>.body.style.opacity = <span class="hljs-number">0.3</span>; <span class="hljs-comment">// (1) 开始指示（indication）</span>


  <span class="hljs-keyword">return</span> loadJson(<span class="hljs-string">`https://api.github.com/users/<span class="hljs-subst">${name}</span>`</span>)

    .finally(<span class="hljs-function">() =&gt;</span> { <span class="hljs-comment">// (2) 停止指示（indication）</span>
      <span class="hljs-built_in">document</span>.body.style.opacity = <span class="hljs-string">&#x27;&#x27;</span>;
      <span class="hljs-keyword">return</span> <span class="hljs-keyword">new</span> <span class="hljs-built_in">Promise</span>(<span class="hljs-function"><span class="hljs-params">resolve</span> =&gt;</span> <span class="hljs-built_in">setTimeout</span>(resolve)); <span class="hljs-comment">// (*)</span>
    })

    .then(<span class="hljs-function"><span class="hljs-params">user</span> =&gt;</span> {
      alert(<span class="hljs-string">`Full name: <span class="hljs-subst">${user.name}</span>.`</span>);
      <span class="hljs-keyword">return</span> user;
    })
    .catch(<span class="hljs-function"><span class="hljs-params">err</span> =&gt;</span> {
      <span class="hljs-keyword">if</span> (err <span class="hljs-keyword">instanceof</span> HttpError &amp;&amp; err.response.status == <span class="hljs-number">404</span>) {
        alert(<span class="hljs-string">&quot;No such user, please reenter.&quot;</span>);
        <span class="hljs-keyword">return</span> demoGithubUser();
      } <span class="hljs-keyword">else</span> {
        <span class="hljs-keyword">throw</span> err;
      }
    });
}

demoGithubUser();</code></pre>
<p>此处的 <code>(1)</code> 行，我们通过调暗文档来指示加载。指示方法没有什么问题，可以使用任何类型的指示来代替。</p>
<p>当 promise 得以解决，fetch 可以是成功或者错误，<code>finally</code> 在 <code>(2)</code> 行触发并终止加载指示。</p>
<p>有一个浏览器技巧，<code>(*)</code> 是从 <code>finally</code> 返回零延时（zero-timeout）的 promise。这是因为一些浏览器（比如 Chrome）需要“一点时间”外的 promise 处理程序来绘制文档的更改。因此它确保在进入链下一步之前，指示在视觉上是停止的。</p>
