<h1 id="错误处理，trycatch">错误处理，&quot;try..catch&quot;</h1>
<p>不管你多么精通编程，有时我们的脚本总还是会出现错误。可能是因为我们的编写出错，或是与预期不同的用户输入，或是错误的服务端响应以及其他数千种原因。</p>
<p>通常，如果发生错误，脚本就会“死亡”（立即停止），并在控制台将错误打印出来。</p>
<p>但是有一种语法结构 <code>try..catch</code>，它使我们可以“捕获（catch）”错误，因此脚本可以执行更合理的操作，而不是死掉。</p>
<h2 id="trycatch-语法">&quot;try..catch&quot; 语法</h2>
<p><code>try..catch</code> 结构由两部分组成：<code>try</code> 和 <code>catch</code>：</p>
<pre><code class="language-js"><span class="hljs-keyword">try</span> {

  <span class="hljs-comment">// 代码...</span>

} <span class="hljs-keyword">catch</span> (err) {

  <span class="hljs-comment">// 错误捕获</span>

}</code></pre>
<p>它按照以下步骤执行：</p>
<ol>
<li>首先，执行 <code>try {...}</code> 中的代码。</li>
<li>如果这里没有错误，则忽略 <code>catch(err)</code>：执行到 <code>try</code> 的末尾并跳过 <code>catch</code> 继续执行。</li>
<li>如果这里出现错误，则 <code>try</code> 执行停止，控制流转向 <code>catch(err)</code> 的开头。变量 <code>err</code>（我们可以使用任何名称）将包含一个 error 对象，该对象包含了所发生事件的详细信息。</li>
</ol>
<p><img src="try-catch-flow.svg" alt=""></p>
<p>所以，<code>try {…}</code> 块内的错误不会杀死脚本 — 我们有机会在 <code>catch</code> 中处理它。</p>
<p>让我们来看一些例子。</p>
<ul>
<li><p>没有 error 的例子：显示 <code>alert</code> <code>(1)</code> 和 <code>(2)</code>：</p>
<pre><code class="language-js"><span class="hljs-keyword">try</span> {

  alert(<span class="hljs-string">&#x27;Start of try runs&#x27;</span>);  <span class="hljs-comment">// (1) &lt;--</span>

  <span class="hljs-comment">// ...这里没有 error</span>

  alert(<span class="hljs-string">&#x27;End of try runs&#x27;</span>);   <span class="hljs-comment">// (2) &lt;--</span>

} <span class="hljs-keyword">catch</span>(err) {

  alert(<span class="hljs-string">&#x27;Catch is ignored, because there are no errors&#x27;</span>); <span class="hljs-comment">// (3)</span>

}</code></pre>
</li>
<li><p>包含 error 的例子：显示 <code>(1)</code> 和 <code>(3)</code> 行的 <code>alert</code> 中的内容：</p>
<pre><code class="language-js"><span class="hljs-keyword">try</span> {

  alert(<span class="hljs-string">&#x27;Start of try runs&#x27;</span>);  <span class="hljs-comment">// (1) &lt;--</span>


  lalala; <span class="hljs-comment">// Error，变量未定义！</span>


  alert(<span class="hljs-string">&#x27;End of try (never reached)&#x27;</span>);  <span class="hljs-comment">// (2)</span>

} <span class="hljs-keyword">catch</span>(err) {

  alert(<span class="hljs-string">`Error has occurred!`</span>); <span class="hljs-comment">// (3) &lt;--</span>

}</code></pre>
</li>
</ul>
<p>`&quot;<code>try..catch</code> 仅对运行时的 error 有效&quot;
要使得 <code>try..catch</code> 能工作，代码必须是可执行的。换句话说，它必须是有效的 JavaScript 代码。</p>
<p>如果代码包含语法错误，那么 <code>try..catch</code> 将无法正常工作，例如含有不匹配的花括号：</p>
<pre><code class="language-js"><span class="hljs-keyword">try</span> {
  error
} <span class="hljs-keyword">catch</span>(e) {
  alert(<span class="hljs-string">&quot;The engine can&#x27;t understand this code, it&#x27;s invalid&quot;</span>);
}</code></pre>
<p>JavaScript 引擎首先会读取代码，然后运行它。在读取阶段发生的错误被称为“解析时间（parse-time）”错误，并且无法恢复（从该代码内部）。这是因为引擎无法理解该代码。</p>
<p>所以，<code>try..catch</code> 只能处理有效代码中出现的错误。这类错误被称为“运行时的错误（runtime errors）”，有时被称为“异常（exceptions）”。</p>
<pre><code>

`&quot;`try..catch` 同步工作&quot;
如果在“计划的（scheduled）”代码中发生异常，例如在 `setTimeout` 中，则 `try..catch` 不会捕获到异常：

```js
try {
  setTimeout(function() {
    noSuchVariable; // 脚本将在这里停止运行
  }, 1000);
} catch (e) {
  alert( &quot;won&#x27;t work&quot; );
}
```

因为 `try..catch` 包裹了计划要执行的函数，该函数本身要稍后才执行，这时引擎已经离开了 `try..catch` 结构。

为了捕获到计划的（scheduled）函数中的异常，那么 `try..catch` 必须在这个函数内：
```js
setTimeout(function() {
  try {
    noSuchVariable; // try..catch 处理 error 了！
  } catch {
    alert( &quot;error is caught here!&quot; );
  }
}, 1000);
```</code></pre>
<h2 id="error-对象">Error 对象</h2>
<p>发生错误时，JavaScript 生成一个包含有关其详细信息的对象。然后将该对象作为参数传递给 <code>catch</code>：</p>
<pre><code class="language-js"><span class="hljs-keyword">try</span> {
  <span class="hljs-comment">// ...</span>
} <span class="hljs-keyword">catch</span>(err) { <span class="hljs-comment">// &lt;-- “error 对象”，也可以用其他参数名代替 err</span>
  <span class="hljs-comment">// ...</span>
}</code></pre>
<p>对于所有内建的 error，error 对象具有两个主要属性：</p>
<p><code>name</code>
: Error 名称。例如，对于一个未定义的变量，名称是 <code>&quot;ReferenceError&quot;</code>。</p>
<p><code>message</code>
: 关于 error 的详细文字描述。</p>
<p>还有其他非标准的属性在大多数环境中可用。其中被最广泛使用和支持的是：</p>
<p><code>stack</code>
: 当前的调用栈：用于调试目的的一个字符串，其中包含有关导致 error 的嵌套调用序列的信息。</p>
<p>例如：</p>
<pre><code class="language-js"><span class="hljs-keyword">try</span> {

  lalala; <span class="hljs-comment">// error, variable is not defined!</span>

} <span class="hljs-keyword">catch</span>(err) {
  alert(err.name); <span class="hljs-comment">// ReferenceError</span>
  alert(err.message); <span class="hljs-comment">// lalala is not defined</span>
  alert(err.stack); <span class="hljs-comment">// ReferenceError: lalala is not defined at (...call stack)</span>

  <span class="hljs-comment">// 也可以将一个 error 作为整体显示出来as a whole</span>
  <span class="hljs-comment">// Error 信息被转换为像 &quot;name: message&quot; 这样的字符串</span>
  alert(err); <span class="hljs-comment">// ReferenceError: lalala is not defined</span>
}</code></pre>
<h2 id="可选的-catch-绑定">可选的 &quot;catch&quot; 绑定</h2>
<p>[recent browser=new]</p>
<p>如果我们不需要 error 的详细信息，<code>catch</code> 也可以忽略它：</p>
<pre><code class="language-js"><span class="hljs-keyword">try</span> {
  <span class="hljs-comment">// ...</span>
} <span class="hljs-keyword">catch</span> { <span class="hljs-comment">// &lt;-- 没有 (err)</span>
  <span class="hljs-comment">// ...</span>
}</code></pre>
<h2 id="使用-trycatch">使用 &quot;try..catch&quot;</h2>
<p>让我们一起探究一下真实场景中 <code>try..catch</code> 的用例。</p>
<p>正如我们所知道的，JavaScript 支持 <a href="mdn:js/JSON/parse">JSON.parse(str)</a> 方法来解析 JSON 编码的值。</p>
<p>通常，它被用来解析从网络，从服务器或是从其他来源接收到的数据。</p>
<p>我们收到数据后，然后像下面这样调用 <code>JSON.parse</code>：</p>
<pre><code class="language-js"><span class="hljs-keyword">let</span> json = <span class="hljs-string">&#x27;{&quot;name&quot;:&quot;John&quot;, &quot;age&quot;: 30}&#x27;</span>; <span class="hljs-comment">// 来自服务器的数据</span>


<span class="hljs-keyword">let</span> user = <span class="hljs-built_in">JSON</span>.parse(json); <span class="hljs-comment">// 将文本表示转换成 JS 对象</span>


<span class="hljs-comment">// 现在 user 是一个解析自 json 字符串的有自己属性的对象</span>
alert( user.name ); <span class="hljs-comment">// John</span>
alert( user.age );  <span class="hljs-comment">// 30</span></code></pre>
<p>你可以在 <a href="info:json">info:json</a> 一章中找到更多关于 JSON 的详细内容。</p>
<p><strong>如果 <code>json</code> 格式错误，<code>JSON.parse</code> 就会生成一个 error，因此脚本就会“死亡”。</strong></p>
<p>我们对此满意吗？当然不！</p>
<p>如果这样做，当拿到的数据出了问题，那么访问者永远都不会知道原因（除非他们打开开发者控制台）。代码执行失败却没有提示信息，这真的是很糟糕的用户体验。</p>
<p>让我们用 <code>try..catch</code> 来处理这个 error：</p>
<pre><code class="language-js"><span class="hljs-keyword">let</span> json = <span class="hljs-string">&quot;{ bad json }&quot;</span>;

<span class="hljs-keyword">try</span> {


  <span class="hljs-keyword">let</span> user = <span class="hljs-built_in">JSON</span>.parse(json); <span class="hljs-comment">// &lt;-- 当出现一个 error 时...</span>

  alert( user.name ); <span class="hljs-comment">// 不工作</span>

} <span class="hljs-keyword">catch</span> (e) {

  <span class="hljs-comment">// ...执行会跳转到这里并继续执行</span>
  alert( <span class="hljs-string">&quot;Our apologies, the data has errors, we&#x27;ll try to request it one more time.&quot;</span> );
  alert( e.name );
  alert( e.message );

}</code></pre>
<p>在这儿，我们将 <code>catch</code> 块仅仅用于显示信息，但是我们可以做更多的事儿：发送一个新的网络请求，向访问者建议一个替代方案，将有关错误的信息发送给记录日志的设备，……。所有这些都比代码“死掉”好得多。</p>
<h2 id="抛出我们自定义的-error">抛出我们自定义的 error</h2>
<p>如果这个 <code>json</code> 在语法上是正确的，但是没有所必须的 <code>name</code> 属性该怎么办？</p>
<p>像这样：</p>
<pre><code class="language-js"><span class="hljs-keyword">let</span> json = <span class="hljs-string">&#x27;{ &quot;age&quot;: 30 }&#x27;</span>; <span class="hljs-comment">// 不完整的数据</span>

<span class="hljs-keyword">try</span> {

  <span class="hljs-keyword">let</span> user = <span class="hljs-built_in">JSON</span>.parse(json); <span class="hljs-comment">// &lt;-- 没有 error</span>

  alert( user.name ); <span class="hljs-comment">// 没有 name！</span>


} <span class="hljs-keyword">catch</span> (e) {
  alert( <span class="hljs-string">&quot;doesn&#x27;t execute&quot;</span> );
}</code></pre>
<p>这里 <code>JSON.parse</code> 正常执行，但是缺少 <code>name</code> 属性对我们来说确实是个 error。</p>
<p>为了统一进行 error 处理，我们将使用 <code>throw</code> 操作符。</p>
<h3 id="throw-操作符">&quot;Throw&quot; 操作符</h3>
<p><code>throw</code> 操作符会生成一个 error 对象。</p>
<p>语法如下：</p>
<pre><code class="language-js"><span class="hljs-keyword">throw</span> <span class="xml"><span class="hljs-tag">&lt;<span class="hljs-name">error</span> <span class="hljs-attr">object</span>&gt;</span></span></code></pre>
<p>技术上讲，我们可以将任何东西用作 error 对象。甚至可以是一个原始类型数据，例如数字或字符串，但最好使用对象，最好使用具有 <code>name</code> 和 <code>message</code> 属性的对象（某种程度上保持与内建 error 的兼容性）。</p>
<p>JavaScript 中有很多内建的标准 error 的构造器：<code>Error</code>，<code>SyntaxError</code>，<code>ReferenceError</code>，<code>TypeError</code> 等。我们也可以使用它们来创建 error 对象。</p>
<p>它们的语法是：</p>
<pre><code class="language-js"><span class="hljs-keyword">let</span> error = <span class="hljs-keyword">new</span> <span class="hljs-built_in">Error</span>(message);
<span class="hljs-comment">// 或</span>
<span class="hljs-keyword">let</span> error = <span class="hljs-keyword">new</span> <span class="hljs-built_in">SyntaxError</span>(message);
<span class="hljs-keyword">let</span> error = <span class="hljs-keyword">new</span> <span class="hljs-built_in">ReferenceError</span>(message);
<span class="hljs-comment">// ...</span></code></pre>
<p>对于内建的 error（不是对于其他任何对象，仅仅是对于 error），<code>name</code> 属性刚好就是构造器的名字。<code>message</code> 则来自于参数（argument）。</p>
<p>例如：</p>
<pre><code class="language-js"><span class="hljs-keyword">let</span> error = <span class="hljs-keyword">new</span> <span class="hljs-built_in">Error</span>(<span class="hljs-string">&quot;Things happen o_O&quot;</span>);

alert(error.name); <span class="hljs-comment">// Error</span>
alert(error.message); <span class="hljs-comment">// Things happen o_O</span></code></pre>
<p>让我们来看看 <code>JSON.parse</code> 会生成什么样的 error：</p>
<pre><code class="language-js"><span class="hljs-keyword">try</span> {
  <span class="hljs-built_in">JSON</span>.parse(<span class="hljs-string">&quot;{ bad json o_O }&quot;</span>);
} <span class="hljs-keyword">catch</span>(e) {

  alert(e.name); <span class="hljs-comment">// SyntaxError</span>

  alert(e.message); <span class="hljs-comment">// Unexpected token b in JSON at position 2</span>
}</code></pre>
<p>正如我们所看到的， 那是一个  <code>SyntaxError</code>。</p>
<p>在我们的示例中，缺少 <code>name</code> 属性就是一个 error，因为用户必须有一个 <code>name</code>。</p>
<p>所以，让我们抛出这个 error。</p>
<pre><code class="language-js"><span class="hljs-keyword">let</span> json = <span class="hljs-string">&#x27;{ &quot;age&quot;: 30 }&#x27;</span>; <span class="hljs-comment">// 不完整的数据</span>

<span class="hljs-keyword">try</span> {

  <span class="hljs-keyword">let</span> user = <span class="hljs-built_in">JSON</span>.parse(json); <span class="hljs-comment">// &lt;-- 没有 error</span>

  <span class="hljs-keyword">if</span> (!user.name) {

    <span class="hljs-keyword">throw</span> <span class="hljs-keyword">new</span> <span class="hljs-built_in">SyntaxError</span>(<span class="hljs-string">&quot;Incomplete data: no name&quot;</span>); <span class="hljs-comment">// (*)</span>

  }

  alert( user.name );

} <span class="hljs-keyword">catch</span>(e) {
  alert( <span class="hljs-string">&quot;JSON Error: &quot;</span> + e.message ); <span class="hljs-comment">// JSON Error: Incomplete data: no name</span>
}</code></pre>
<p>在 <code>(*)</code> 标记的这一行，<code>throw</code> 操作符生成了包含着我们所给定的 <code>message</code> 的 <code>SyntaxError</code>，与 JavaScript 自己生成的方式相同。<code>try</code> 的执行立即停止，控制流转向 <code>catch</code> 块。</p>
<p>现在，<code>catch</code> 成为了所有 error 处理的唯一场所：对于 <code>JSON.parse</code> 和其他情况都适用。</p>
<h2 id="再次抛出（rethrowing）">再次抛出（Rethrowing）</h2>
<p>在上面的例子中，我们使用 <code>try..catch</code> 来处理不正确的数据。但是在 <code>try {...}</code> 块中是否可能发生 <strong>另一个预料之外的 error</strong>？例如编程错误（未定义变量）或其他错误，而不仅仅是这种“不正确的数据”。</p>
<p>例如：</p>
<pre><code class="language-js"><span class="hljs-keyword">let</span> json = <span class="hljs-string">&#x27;{ &quot;age&quot;: 30 }&#x27;</span>; <span class="hljs-comment">// 不完整的数据</span>

<span class="hljs-keyword">try</span> {
  user = <span class="hljs-built_in">JSON</span>.parse(json); <span class="hljs-comment">// &lt;-- 忘记在 user 前放置 &quot;let&quot;</span>

  <span class="hljs-comment">// ...</span>
} <span class="hljs-keyword">catch</span>(err) {
  alert(<span class="hljs-string">&quot;JSON Error: &quot;</span> + err); <span class="hljs-comment">// JSON Error: ReferenceError: user is not defined</span>
  <span class="hljs-comment">// (实际上并没有 JSON Error)</span>
}</code></pre>
<p>当然，一切皆有可能！程序员也会犯错。即使是被数百万人使用了几十年的开源项目中 — 也可能突然被发现了一个漏洞，并导致可怕的黑客入侵。</p>
<p>在我们的例子中，<code>try..catch</code> 旨在捕获“数据不正确”的 error。但是实际上，catch 会捕获到 <strong>所有</strong> 来自于 <code>try</code> 的 error。在这儿，它捕获到了一个预料之外的 error，但是仍然抛出的是同样的 <code>&quot;JSON Error&quot;</code> 信息。这是不正确的，并且也会使代码变得更难以调试。</p>
<p>为了避免此类问题，我们可以采用“重新抛出”技术。规则很简单：</p>
<p><strong><code>catch</code> 应该只处理它知道的 error，并“抛出”所有其他 error。</strong></p>
<p>“再次抛出（rethrowing）”技术可以被更详细地解释为：</p>
<ol>
<li>Catch 捕获所有 error。</li>
<li>在 <code>catch(err) {...}</code> 块中，我们对 error 对象 <code>err</code> 进行分析。</li>
<li>如果我们不知道如何处理它，那我们就 <code>throw err</code>。</li>
</ol>
<p>通常，我们可以使用 <code>instanceof</code> 操作符判断错误类型：</p>
<pre><code class="language-js"><span class="hljs-keyword">try</span> {
  user = { <span class="hljs-comment">/*...*/</span> };
} <span class="hljs-keyword">catch</span>(err) {

  <span class="hljs-keyword">if</span> (err <span class="hljs-keyword">instanceof</span> <span class="hljs-built_in">ReferenceError</span>) {

    alert(<span class="hljs-string">&#x27;ReferenceError&#x27;</span>); <span class="hljs-comment">// 访问一个未定义（undefined）的变量产生了 &quot;ReferenceError&quot;</span>
  }
}</code></pre>
<p>我们还可以从 <code>err.name</code> 属性中获取错误的类名。所有原生的错误都有这个属性。另一种方式是读取 <code>err.constructor.name</code>。</p>
<p>在下面的代码中，我们使用“再次抛出”，以达到在 <code>catch</code> 中只处理 <code>SyntaxError</code> 的目的：</p>
<pre><code class="language-js"><span class="hljs-keyword">let</span> json = <span class="hljs-string">&#x27;{ &quot;age&quot;: 30 }&#x27;</span>; <span class="hljs-comment">// 不完整的数据</span>
<span class="hljs-keyword">try</span> {

  <span class="hljs-keyword">let</span> user = <span class="hljs-built_in">JSON</span>.parse(json);

  <span class="hljs-keyword">if</span> (!user.name) {
    <span class="hljs-keyword">throw</span> <span class="hljs-keyword">new</span> <span class="hljs-built_in">SyntaxError</span>(<span class="hljs-string">&quot;Incomplete data: no name&quot;</span>);
  }


  blabla(); <span class="hljs-comment">// 预料之外的 error</span>


  alert( user.name );

} <span class="hljs-keyword">catch</span>(e) {


  <span class="hljs-keyword">if</span> (e <span class="hljs-keyword">instanceof</span> <span class="hljs-built_in">SyntaxError</span>) {
    alert( <span class="hljs-string">&quot;JSON Error: &quot;</span> + e.message );
  } <span class="hljs-keyword">else</span> {
    <span class="hljs-keyword">throw</span> e; <span class="hljs-comment">// 再次抛出 (*)</span>
  }


}</code></pre>
<p>如果 <code>(*)</code> 标记的这行 <code>catch</code> 块中的 error 从 <code>try..catch</code> 中“掉了出来”，那么它也可以被外部的 <code>try..catch</code> 结构（如果存在）捕获到，如果外部不存在这种结构，那么脚本就会被杀死。</p>
<p>所以，<code>catch</code> 块实际上只处理它知道该如何处理的 error，并“跳过”所有其他的 error。</p>
<p>下面这个示例演示了这种类型的 error 是如何被另外一级 <code>try..catch</code> 捕获的：</p>
<pre><code class="language-js"><span class="hljs-function"><span class="hljs-keyword">function</span> <span class="hljs-title">readData</span>(<span class="hljs-params"></span>) </span>{
  <span class="hljs-keyword">let</span> json = <span class="hljs-string">&#x27;{ &quot;age&quot;: 30 }&#x27;</span>;

  <span class="hljs-keyword">try</span> {
    <span class="hljs-comment">// ...</span>

    blabla(); <span class="hljs-comment">// error!</span>

  } <span class="hljs-keyword">catch</span> (e) {
    <span class="hljs-comment">// ...</span>
    <span class="hljs-keyword">if</span> (!(e <span class="hljs-keyword">instanceof</span> <span class="hljs-built_in">SyntaxError</span>)) {

      <span class="hljs-keyword">throw</span> e; <span class="hljs-comment">// 再次抛出（不知道如何处理它）</span>

    }
  }
}

<span class="hljs-keyword">try</span> {
  readData();
} <span class="hljs-keyword">catch</span> (e) {

  alert( <span class="hljs-string">&quot;External catch got: &quot;</span> + e ); <span class="hljs-comment">// 捕获了它！</span>

}</code></pre>
<p>上面这个例子中的 <code>readData</code> 只知道如何处理 <code>SyntaxError</code>，而外部的 <code>try..catch</code> 知道如何处理任意的 error。</p>
<h2 id="trycatchfinally">try..catch..finally</h2>
<p>等一下，以上并不是所有内容。</p>
<p><code>try..catch</code> 结构可能还有一个代码子句（clause）：<code>finally</code>。</p>
<p>如果它存在，它在所有情况下都会被执行：</p>
<ul>
<li><code>try</code> 之后，如果没有 error，</li>
<li><code>catch</code> 之后，如果没有 error。</li>
</ul>
<p>该扩展语法如下所示：</p>
<pre><code class="language-js"><span class="hljs-keyword">try</span> {
   ... 尝试执行的代码 ...
} <span class="hljs-keyword">catch</span>(e) {
   ... 处理 error ...
} <span class="hljs-keyword">finally</span> {
   ... 总是会执行的代码 ...
}</code></pre>
<p>试试运行这段代码：</p>
<pre><code class="language-js"><span class="hljs-keyword">try</span> {
  alert( <span class="hljs-string">&#x27;try&#x27;</span> );
  <span class="hljs-keyword">if</span> (confirm(<span class="hljs-string">&#x27;Make an error?&#x27;</span>)) BAD_CODE();
} <span class="hljs-keyword">catch</span> (e) {
  alert( <span class="hljs-string">&#x27;catch&#x27;</span> );
} <span class="hljs-keyword">finally</span> {
  alert( <span class="hljs-string">&#x27;finally&#x27;</span> );
}</code></pre>
<p>这段代码有两种执行方式：</p>
<ol>
<li>如果你对于 &quot;Make an error?&quot; 的回答是 &quot;Yes&quot;，那么执行 <code>try -&gt; catch -&gt; finally</code>。</li>
<li>如果你的回答是 &quot;No&quot;，那么执行 <code>try -&gt; finally</code>。</li>
</ol>
<p><code>finally</code> 子句（clause）通常用在：当我们开始做某事的时候，希望无论出现什么情况都要完成完成某个任务。</p>
<p>例如，我们想要测量一个斐波那契数字函数 <code>fib(n)</code> 执行所需要花费的时间。通常，我们可以在运行它之前开始测量，并在运行完成时结束测量。但是，如果在该函数调用期间出现 error 该怎么办？特别是，下面这段 <code>fib(n)</code> 的实现代码在遇到负数或非整数数字时会返回一个 error。</p>
<p>无论如何，<code>finally</code> 子句都是一个结束测量的好地方。</p>
<p>在这儿，<code>finally</code> 能够保证在两种情况下都能正确地测量时间 — 成功执行 <code>fib</code> 以及 <code>fib</code> 中出现 error 时：</p>
<pre><code class="language-js"><span class="hljs-keyword">let</span> num = +prompt(<span class="hljs-string">&quot;Enter a positive integer number?&quot;</span>, <span class="hljs-number">35</span>)

<span class="hljs-keyword">let</span> diff, result;

<span class="hljs-function"><span class="hljs-keyword">function</span> <span class="hljs-title">fib</span>(<span class="hljs-params">n</span>) </span>{
  <span class="hljs-keyword">if</span> (n &lt; <span class="hljs-number">0</span> || <span class="hljs-built_in">Math</span>.trunc(n) != n) {
    <span class="hljs-keyword">throw</span> <span class="hljs-keyword">new</span> <span class="hljs-built_in">Error</span>(<span class="hljs-string">&quot;Must not be negative, and also an integer.&quot;</span>);
  }
  <span class="hljs-keyword">return</span> n &lt;= <span class="hljs-number">1</span> ? n : fib(n - <span class="hljs-number">1</span>) + fib(n - <span class="hljs-number">2</span>);
}

<span class="hljs-keyword">let</span> start = <span class="hljs-built_in">Date</span>.now();

<span class="hljs-keyword">try</span> {
  result = fib(num);
} <span class="hljs-keyword">catch</span> (e) {
  result = <span class="hljs-number">0</span>;

} <span class="hljs-keyword">finally</span> {
  diff = <span class="hljs-built_in">Date</span>.now() - start;
}


alert(result || <span class="hljs-string">&quot;error occurred&quot;</span>);

alert( <span class="hljs-string">`execution took <span class="hljs-subst">${diff}</span>ms`</span> );</code></pre>
<p>你可以通过运行上面这段代码并在 <code>prompt</code> 弹窗中输入 <code>35</code> 来进行检查 — 代码运行正常，先执行 <code>try</code> 然后是 <code>finally</code>。如果你输入的是 <code>-1</code> — 将立即出现 error，执行将只花费 <code>0ms</code>。以上两种情况下的时间测量都正确地完成了。</p>
<p>换句话说，函数 <code>fib</code> 以 <code>return</code> 还是 <code>throw</code> 完成都无关紧要。在这两种情况下都会执行 <code>finally</code> 子句。</p>
<p>```smart header=&quot;变量和 <code>try..catch..finally</code> 中的局部变量&quot;
请注意，上面代码中的 <code>result</code> 和 <code>diff</code> 变量都是在 <code>try..catch</code> <strong>之前</strong> 声明的。</p>
<p>否则，如果我们使用 <code>let</code> 在 <code>try</code> 块中声明变量，那么该变量将只在 <code>try</code> 块中可见。</p>
<pre><code>
````smart header=&quot;`finally` 和 `return`&quot;
`finally` 子句适用于 `try..catch` 的 **任何** 出口。这包括显式的 `return`。

在下面这个例子中，在 `try` 中有一个 `return`。在这种情况下，`finally` 会在控制转向外部代码前被执行。

```js
function func() {

  try {

    return 1;


  } catch (e) {
    /* ... */
  } finally {

    alert( &#x27;finally&#x27; );

  }
}

alert( func() ); // 先执行 finally 中的 alert，然后执行这个 alert</code></pre>
<pre><code>
````smart header=&quot;`try..finally`&quot;

没有 `catch` 子句的 `try..finally` 结构也很有用。当我们不想在这儿处理 error（让它们 fall through），但是需要确保我们启动的处理需要被完成。

```js
function func() {
  // 开始执行需要被完成的操作（比如测量）
  try {
    // ...
  } finally {
    // 完成前面我们需要完成的那件事儿，即使 try 中的执行失败了
  }
}
```
上面的代码中，由于没有 `catch`，所以 `try` 中的 error 总是会使代码执行跳转至函数 `func()` 外。但是，在跳出之前需要执行 `finally` 中的代码。</code></pre>
<h2 id="全局-catch">全局 catch</h2>
<pre><code class="language-warn">这个部分的内容并不是 JavaScript 核心的一部分。</code></pre>
<p>设想一下，在 <code>try..catch</code> 结构外有一个致命的 error，然后脚本死亡了。这个 error 就像编程错误或其他可怕的事儿那样。</p>
<p>有什么办法可以用来应对这种情况吗？我们可能想要记录这个 error，并向用户显示某些内容（通常用户看不到错误信息）等。</p>
<p>规范中没有相关内容，但是代码的执行环境一般会提供这种机制，因为它确实很有用。例如，Node.JS 有 <a href="https://nodejs.org/api/process.html#process_event_uncaughtexception"><code>process.on(&quot;uncaughtException&quot;)</code></a>。在浏览器中，我们可以将将一个函数赋值给特殊的 <a href="mdn:api/GlobalEventHandlers/onerror">window.onerror</a> 属性，该函数将在发生未捕获的 error 时执行。</p>
<p>语法如下：</p>
<pre><code class="language-js"><span class="hljs-built_in">window</span>.onerror = <span class="hljs-function"><span class="hljs-keyword">function</span>(<span class="hljs-params">message, url, line, col, error</span>) </span>{
  <span class="hljs-comment">// ...</span>
};</code></pre>
<p><code>message</code>
: Error 信息。</p>
<p><code>url</code>
: 发生 error 的脚本的 URL。</p>
<p><code>line</code>，<code>col</code>
: 发生 error 处的代码的行号和列号。</p>
<p><code>error</code>
: Error 对象。</p>
<p>例如：</p>
<pre><code class="language-html"><span class="hljs-tag">&lt;<span class="hljs-name">script</span>&gt;</span><span class="javascript">

  <span class="hljs-built_in">window</span>.onerror = <span class="hljs-function"><span class="hljs-keyword">function</span>(<span class="hljs-params">message, url, line, col, error</span>) </span>{
    alert(<span class="hljs-string">`<span class="hljs-subst">${message}</span>\n At <span class="hljs-subst">${line}</span>:<span class="hljs-subst">${col}</span> of <span class="hljs-subst">${url}</span>`</span>);
  };


  <span class="hljs-function"><span class="hljs-keyword">function</span> <span class="hljs-title">readData</span>(<span class="hljs-params"></span>) </span>{
    badFunc(); <span class="hljs-comment">// 啊，出问题了！</span>
  }

  readData();
</span><span class="hljs-tag">&lt;/<span class="hljs-name">script</span>&gt;</span></code></pre>
<p>全局错误处理程序 <code>window.onerror</code> 的作用通常不是恢复脚本的执行 — 如果发生编程错误，那这几乎是不可能的，它的作用是将错误信息发送给开发者。</p>
<p>也有针对这种情况提供错误日志的 Web 服务，例如 <a href="https://errorception.com">https://errorception.com</a> 或 <a href="http://www.muscula.com">http://www.muscula.com</a>。</p>
<p>它们会像这样运行：</p>
<ol>
<li>我们注册该服务，并拿到一段 JS 代码（或脚本的 URL），然后插入到页面中。</li>
<li>该 JS 脚本设置了自定义的 <code>window.onerror</code> 函数。</li>
<li>当发生 error 时，它会发送一个此 error  相关的网络请求到服务提供方。</li>
<li>我们可以登录到服务方的 Web 界面来查看这些 error。</li>
</ol>
<h2 id="总结">总结</h2>
<p><code>try..catch</code> 结构允许我们处理执行过程中出现的 error。从字面上看，它允许“尝试”运行代码并“捕获”其中可能发生的错误。</p>
<p>语法如下：</p>
<pre><code class="language-js"><span class="hljs-keyword">try</span> {
  <span class="hljs-comment">// 执行此处代码</span>
} <span class="hljs-keyword">catch</span>(err) {
  <span class="hljs-comment">// 如果发生错误，跳转至此处</span>
  <span class="hljs-comment">// err 是一个 error 对象</span>
} <span class="hljs-keyword">finally</span> {
  <span class="hljs-comment">// 无论怎样都会在 try/catch 之后执行</span>
}</code></pre>
<p>这儿可能会没有 <code>catch</code> 部分或者没有 <code>finally</code>，所以 <code>try..catch</code> 或 <code>try..finally</code> 都是可用的。</p>
<p>Error 对象包含下列属性：</p>
<ul>
<li><code>message</code> — 人类可读的 error 信息。</li>
<li><code>name</code> — 具有 error 名称的字符串（Error 构造器的名称）。</li>
<li><code>stack</code>（没有标准，但得到了很好的支持）— Error 发生时的调用栈。</li>
</ul>
<p>如果我们不需要 error 对象，我们可以通过使用 <code>catch {</code> 而不是 <code>catch(err) {</code> 来省略它。</p>
<p>我们也可以使用 <code>throw</code> 操作符来生成自定义的 error。从技术上讲，<code>throw</code> 的参数可以是任何东西，但通常是继承自内建的 <code>Error</code> 类的 error 对象。下一章我们会详细介绍扩展 error。</p>
<p>再次抛出（rethrowing）是一种错误处理的重要模式：<code>catch</code> 块通常期望并知道如何处理特定的 error 类型，因此它应该再次抛出它不知道的 error。</p>
<p>即使我们没有 <code>try..catch</code>，大多数执行环境也允许我们设置“全局”错误处理程序来捕获“掉出（fall out）”的 error。在浏览器中，就是 <code>window.onerror</code>。</p>
